2021-12-02 09:13:14,021 [29] ERROR  Application (null) (null) - Name:AQ\11173
2021-12-02 09:13:28,977 [29] ERROR  Application (null) (null) -    at System.Data.Entity.Core.EntityClient.EntityConnection.<OpenAsync>d__8.MoveNext()
--- End of stack trace from previous location where exception was thrown ---
   at System.Runtime.CompilerServices.TaskAwaiter.ThrowForNonSuccess(Task task)
   at System.Runtime.CompilerServices.TaskAwaiter.HandleNonSuccessAndDebuggerNotification(Task task)
   at System.Data.Entity.Core.Objects.ObjectContext.<EnsureConnectionAsync>d__9.MoveNext()
--- End of stack trace from previous location where exception was thrown ---
   at System.Runtime.CompilerServices.TaskAwaiter.ThrowForNonSuccess(Task task)
   at System.Runtime.CompilerServices.TaskAwaiter.HandleNonSuccessAndDebuggerNotification(Task task)
   at System.Data.Entity.Core.Objects.ObjectContext.<ExecuteInTransactionAsync>d__3d`1.MoveNext()
--- End of stack trace from previous location where exception was thrown ---
   at System.Runtime.CompilerServices.TaskAwaiter.ThrowForNonSuccess(Task task)
   at System.Runtime.CompilerServices.TaskAwaiter.HandleNonSuccessAndDebuggerNotification(Task task)
   at System.Data.Entity.SqlServer.DefaultSqlExecutionStrategy.<ExecuteAsyncImplementation>d__9`1.MoveNext()
--- End of stack trace from previous location where exception was thrown ---
   at System.Runtime.CompilerServices.TaskAwaiter.ThrowForNonSuccess(Task task)
   at System.Runtime.CompilerServices.TaskAwaiter.HandleNonSuccessAndDebuggerNotification(Task task)
   at System.Data.Entity.Core.Objects.ObjectQuery`1.<GetResultsAsync>d__e.MoveNext()
--- End of stack trace from previous location where exception was thrown ---
   at System.Runtime.CompilerServices.TaskAwaiter.ThrowForNonSuccess(Task task)
   at System.Runtime.CompilerServices.TaskAwaiter.HandleNonSuccessAndDebuggerNotification(Task task)
   at System.Data.Entity.Internal.LazyAsyncEnumerator`1.<FirstMoveNextAsync>d__0.MoveNext()
--- End of stack trace from previous location where exception was thrown ---
   at System.Runtime.CompilerServices.TaskAwaiter.ThrowForNonSuccess(Task task)
   at System.Runtime.CompilerServices.TaskAwaiter.HandleNonSuccessAndDebuggerNotification(Task task)
   at System.Data.Entity.Infrastructure.IDbAsyncEnumerableExtensions.<FirstOrDefaultAsync>d__25`1.MoveNext()
--- End of stack trace from previous location where exception was thrown ---
   at System.Runtime.CompilerServices.TaskAwaiter.ThrowForNonSuccess(Task task)
   at System.Runtime.CompilerServices.TaskAwaiter.HandleNonSuccessAndDebuggerNotification(Task task)
   at Microsoft.AspNet.Identity.TaskExtensions.CultureAwaiter`1.GetResult()
   at Microsoft.AspNet.Identity.EntityFramework.UserStore`6.<GetUserAggregateAsync>d__67.MoveNext()
--- End of stack trace from previous location where exception was thrown ---
   at System.Runtime.CompilerServices.TaskAwaiter.ThrowForNonSuccess(Task task)
   at System.Runtime.CompilerServices.TaskAwaiter.HandleNonSuccessAndDebuggerNotification(Task task)
   at Microsoft.AspNet.Identity.AsyncHelper.RunSync[TResult](Func`1 func)
   at Microsoft.AspNet.Identity.UserManagerExtensions.FindByName[TUser,TKey](UserManager`2 manager, String userName)
   at AQ.Kelloggs.UI.Controllers.CommonController.CheckUser(String username, String env) in D:\Kellogs Projects\Kellogs\AQ.Kelloggs.UI\Controllers\CommonController.cs:line 338
   at AQ.Kelloggs.UI.Controllers.CommonController.Index() in D:\Kellogs Projects\Kellogs\AQ.Kelloggs.UI\Controllers\CommonController.cs:line 268
2021-12-02 09:13:28,979 [29] ERROR  Application (null) (null) - The underlying provider failed on Open.
2021-12-02 09:14:23,481 [29] ERROR  Application (null) (null) - The underlying provider failed on Open.
2021-12-02 09:14:24,003 [54] ERROR  Application (null) (null) - Name:AQ\11173
2021-12-02 09:14:38,637 [54] ERROR  Application (null) (null) -    at System.Data.Entity.Core.EntityClient.EntityConnection.<OpenAsync>d__8.MoveNext()
--- End of stack trace from previous location where exception was thrown ---
   at System.Runtime.CompilerServices.TaskAwaiter.ThrowForNonSuccess(Task task)
   at System.Runtime.CompilerServices.TaskAwaiter.HandleNonSuccessAndDebuggerNotification(Task task)
   at System.Data.Entity.Core.Objects.ObjectContext.<EnsureConnectionAsync>d__9.MoveNext()
--- End of stack trace from previous location where exception was thrown ---
   at System.Runtime.CompilerServices.TaskAwaiter.ThrowForNonSuccess(Task task)
   at System.Runtime.CompilerServices.TaskAwaiter.HandleNonSuccessAndDebuggerNotification(Task task)
   at System.Data.Entity.Core.Objects.ObjectContext.<ExecuteInTransactionAsync>d__3d`1.MoveNext()
--- End of stack trace from previous location where exception was thrown ---
   at System.Runtime.CompilerServices.TaskAwaiter.ThrowForNonSuccess(Task task)
   at System.Runtime.CompilerServices.TaskAwaiter.HandleNonSuccessAndDebuggerNotification(Task task)
   at System.Data.Entity.SqlServer.DefaultSqlExecutionStrategy.<ExecuteAsyncImplementation>d__9`1.MoveNext()
--- End of stack trace from previous location where exception was thrown ---
   at System.Runtime.CompilerServices.TaskAwaiter.ThrowForNonSuccess(Task task)
   at System.Runtime.CompilerServices.TaskAwaiter.HandleNonSuccessAndDebuggerNotification(Task task)
   at System.Data.Entity.Core.Objects.ObjectQuery`1.<GetResultsAsync>d__e.MoveNext()
--- End of stack trace from previous location where exception was thrown ---
   at System.Runtime.CompilerServices.TaskAwaiter.ThrowForNonSuccess(Task task)
   at System.Runtime.CompilerServices.TaskAwaiter.HandleNonSuccessAndDebuggerNotification(Task task)
   at System.Data.Entity.Internal.LazyAsyncEnumerator`1.<FirstMoveNextAsync>d__0.MoveNext()
--- End of stack trace from previous location where exception was thrown ---
   at System.Runtime.CompilerServices.TaskAwaiter.ThrowForNonSuccess(Task task)
   at System.Runtime.CompilerServices.TaskAwaiter.HandleNonSuccessAndDebuggerNotification(Task task)
   at System.Data.Entity.Infrastructure.IDbAsyncEnumerableExtensions.<FirstOrDefaultAsync>d__25`1.MoveNext()
--- End of stack trace from previous location where exception was thrown ---
   at System.Runtime.CompilerServices.TaskAwaiter.ThrowForNonSuccess(Task task)
   at System.Runtime.CompilerServices.TaskAwaiter.HandleNonSuccessAndDebuggerNotification(Task task)
   at Microsoft.AspNet.Identity.TaskExtensions.CultureAwaiter`1.GetResult()
   at Microsoft.AspNet.Identity.EntityFramework.UserStore`6.<GetUserAggregateAsync>d__67.MoveNext()
--- End of stack trace from previous location where exception was thrown ---
   at System.Runtime.CompilerServices.TaskAwaiter.ThrowForNonSuccess(Task task)
   at System.Runtime.CompilerServices.TaskAwaiter.HandleNonSuccessAndDebuggerNotification(Task task)
   at Microsoft.AspNet.Identity.AsyncHelper.RunSync[TResult](Func`1 func)
   at Microsoft.AspNet.Identity.UserManagerExtensions.FindByName[TUser,TKey](UserManager`2 manager, String userName)
   at AQ.Kelloggs.UI.Controllers.CommonController.CheckUser(String username, String env) in D:\Kellogs Projects\Kellogs\AQ.Kelloggs.UI\Controllers\CommonController.cs:line 338
   at AQ.Kelloggs.UI.Controllers.CommonController.Index() in D:\Kellogs Projects\Kellogs\AQ.Kelloggs.UI\Controllers\CommonController.cs:line 268
2021-12-02 09:14:38,646 [54] ERROR  Application (null) (null) - The underlying provider failed on Open.
2021-12-02 13:26:06,005 [54] ERROR  Application (null) (null) - The underlying provider failed on Open.
2021-12-02 13:26:06,202 [31] ERROR  Application (null) (null) - Name:AQ\11173
2021-12-02 13:29:24,794 [13] ERROR  Application (null) (null) - Name:AQ\11173
