2022-01-14 10:31:04,345 [26] ERROR  Application (null) (null) - Name:AQ\11173
2022-01-14 10:31:46,596 [26] ERROR  Application (null) (null) -    at System.Data.Entity.Core.EntityClient.EntityConnection.<OpenAsync>d__8.MoveNext()
--- End of stack trace from previous location where exception was thrown ---
   at System.Runtime.CompilerServices.TaskAwaiter.ThrowForNonSuccess(Task task)
   at System.Runtime.CompilerServices.TaskAwaiter.HandleNonSuccessAndDebuggerNotification(Task task)
   at System.Data.Entity.Core.Objects.ObjectContext.<EnsureConnectionAsync>d__9.MoveNext()
--- End of stack trace from previous location where exception was thrown ---
   at System.Runtime.CompilerServices.TaskAwaiter.ThrowForNonSuccess(Task task)
   at System.Runtime.CompilerServices.TaskAwaiter.HandleNonSuccessAndDebuggerNotification(Task task)
   at System.Data.Entity.Core.Objects.ObjectContext.<ExecuteInTransactionAsync>d__3d`1.MoveNext()
--- End of stack trace from previous location where exception was thrown ---
   at System.Runtime.CompilerServices.TaskAwaiter.ThrowForNonSuccess(Task task)
   at System.Runtime.CompilerServices.TaskAwaiter.HandleNonSuccessAndDebuggerNotification(Task task)
   at System.Data.Entity.SqlServer.DefaultSqlExecutionStrategy.<ExecuteAsyncImplementation>d__9`1.MoveNext()
--- End of stack trace from previous location where exception was thrown ---
   at System.Runtime.CompilerServices.TaskAwaiter.ThrowForNonSuccess(Task task)
   at System.Runtime.CompilerServices.TaskAwaiter.HandleNonSuccessAndDebuggerNotification(Task task)
   at System.Data.Entity.Core.Objects.ObjectQuery`1.<GetResultsAsync>d__e.MoveNext()
--- End of stack trace from previous location where exception was thrown ---
   at System.Runtime.CompilerServices.TaskAwaiter.ThrowForNonSuccess(Task task)
   at System.Runtime.CompilerServices.TaskAwaiter.HandleNonSuccessAndDebuggerNotification(Task task)
   at System.Data.Entity.Internal.LazyAsyncEnumerator`1.<FirstMoveNextAsync>d__0.MoveNext()
--- End of stack trace from previous location where exception was thrown ---
   at System.Runtime.CompilerServices.TaskAwaiter.ThrowForNonSuccess(Task task)
   at System.Runtime.CompilerServices.TaskAwaiter.HandleNonSuccessAndDebuggerNotification(Task task)
   at System.Data.Entity.Infrastructure.IDbAsyncEnumerableExtensions.<FirstOrDefaultAsync>d__25`1.MoveNext()
--- End of stack trace from previous location where exception was thrown ---
   at System.Runtime.CompilerServices.TaskAwaiter.ThrowForNonSuccess(Task task)
   at System.Runtime.CompilerServices.TaskAwaiter.HandleNonSuccessAndDebuggerNotification(Task task)
   at Microsoft.AspNet.Identity.TaskExtensions.CultureAwaiter`1.GetResult()
   at Microsoft.AspNet.Identity.EntityFramework.UserStore`6.<GetUserAggregateAsync>d__67.MoveNext()
--- End of stack trace from previous location where exception was thrown ---
   at System.Runtime.CompilerServices.TaskAwaiter.ThrowForNonSuccess(Task task)
   at System.Runtime.CompilerServices.TaskAwaiter.HandleNonSuccessAndDebuggerNotification(Task task)
   at Microsoft.AspNet.Identity.AsyncHelper.RunSync[TResult](Func`1 func)
   at Microsoft.AspNet.Identity.UserManagerExtensions.FindByName[TUser,TKey](UserManager`2 manager, String userName)
   at AQ.Kelloggs.UI.Controllers.CommonController.CheckUser(String username, String env) in D:\Kellogs Projects\Kellogs\AQ.Kelloggs.UI\Controllers\CommonController.cs:line 338
   at AQ.Kelloggs.UI.Controllers.CommonController.Index() in D:\Kellogs Projects\Kellogs\AQ.Kelloggs.UI\Controllers\CommonController.cs:line 268
2022-01-14 10:31:46,602 [26] ERROR  Application (null) (null) - The underlying provider failed on Open.
2022-01-14 10:44:15,414 [26] ERROR  Application (null) (null) - The underlying provider failed on Open.
2022-01-14 10:44:16,035 [28] ERROR  Application (null) (null) - Name:AQ\11173
2022-01-14 11:44:05,640 [10] ERROR  Application (null) (null) - Name:AQ\11173
